Traceback (most recent call last):
  File "/home/petri/miniforge3/envs/octave/lib/python3.11/site-packages/jupyter_cache/executors/utils.py", line 58, in single_nb_execution
    executenb(
  File "/home/petri/miniforge3/envs/octave/lib/python3.11/site-packages/nbclient/client.py", line 1305, in execute
    return NotebookClient(nb=nb, resources=resources, km=km, **kwargs).execute()
           ^^^^^^^^^^^^^^^^^^^^^^^^^^^^^^^^^^^^^^^^^^^^^^^^^^^^^^^^^^^^^^^^^^^^^
  File "/home/petri/miniforge3/envs/octave/lib/python3.11/site-packages/jupyter_core/utils/__init__.py", line 165, in wrapped
    return loop.run_until_complete(inner)
           ^^^^^^^^^^^^^^^^^^^^^^^^^^^^^^
  File "/home/petri/miniforge3/envs/octave/lib/python3.11/asyncio/base_events.py", line 653, in run_until_complete
    return future.result()
           ^^^^^^^^^^^^^^^
  File "/home/petri/miniforge3/envs/octave/lib/python3.11/site-packages/nbclient/client.py", line 705, in async_execute
    await self.async_execute_cell(
  File "/home/petri/miniforge3/envs/octave/lib/python3.11/site-packages/nbclient/client.py", line 1058, in async_execute_cell
    await self._check_raise_for_error(cell, cell_index, exec_reply)
  File "/home/petri/miniforge3/envs/octave/lib/python3.11/site-packages/nbclient/client.py", line 914, in _check_raise_for_error
    raise CellExecutionError.from_cell_and_msg(cell, exec_reply_content)
nbclient.exceptions.CellExecutionError: An error occurred while executing the following cell:
------------------
# This, a little bit complex statement, chains severa sequential actions together
# 1) group the dataframe WD by an index, called as 'date'
# 2) apply an aggregate fuction first() to the groupped dataframe to replace the 
#    value of each column in a group with the first value observed witin a group
# 3) Take take values observed in July 1987 from the fixed dataframe
# 4) Select all colums, except the first four from the resulting dataframe
WD.groupby('date').first()['1987-07'].iloc[:,4:]
------------------


[0;31m---------------------------------------------------------------------------[0m
[0;31mKeyError[0m                                  Traceback (most recent call last)
File [0;32m~/miniforge3/envs/octave/lib/python3.11/site-packages/pandas/core/indexes/base.py:3802[0m, in [0;36mIndex.get_loc[0;34m(self, key)[0m
[1;32m   3801[0m [38;5;28;01mtry[39;00m:
[0;32m-> 3802[0m     [38;5;28;01mreturn[39;00m [38;5;28;43mself[39;49m[38;5;241;43m.[39;49m[43m_engine[49m[38;5;241;43m.[39;49m[43mget_loc[49m[43m([49m[43mcasted_key[49m[43m)[49m
[1;32m   3803[0m [38;5;28;01mexcept[39;00m [38;5;167;01mKeyError[39;00m [38;5;28;01mas[39;00m err:

File [0;32mindex.pyx:153[0m, in [0;36mpandas._libs.index.IndexEngine.get_loc[0;34m()[0m

File [0;32mindex.pyx:182[0m, in [0;36mpandas._libs.index.IndexEngine.get_loc[0;34m()[0m

File [0;32mpandas/_libs/hashtable_class_helper.pxi:7081[0m, in [0;36mpandas._libs.hashtable.PyObjectHashTable.get_item[0;34m()[0m

File [0;32mpandas/_libs/hashtable_class_helper.pxi:7089[0m, in [0;36mpandas._libs.hashtable.PyObjectHashTable.get_item[0;34m()[0m

[0;31mKeyError[0m: '1987-07'

The above exception was the direct cause of the following exception:

[0;31mKeyError[0m                                  Traceback (most recent call last)
Cell [0;32mIn[27], line 7[0m
[1;32m      1[0m [38;5;66;03m# This, a little bit complex statement, chains severa sequential actions together[39;00m
[1;32m      2[0m [38;5;66;03m# 1) group the dataframe WD by an index, called as 'date'[39;00m
[1;32m      3[0m [38;5;66;03m# 2) apply an aggregate fuction first() to the groupped dataframe to replace the [39;00m
[1;32m      4[0m [38;5;66;03m#    value of each column in a group with the first value observed witin a group[39;00m
[1;32m      5[0m [38;5;66;03m# 3) Take take values observed in July 1987 from the fixed dataframe[39;00m
[1;32m      6[0m [38;5;66;03m# 4) Select all colums, except the first four from the resulting dataframe[39;00m
[0;32m----> 7[0m [43mWD[49m[38;5;241;43m.[39;49m[43mgroupby[49m[43m([49m[38;5;124;43m'[39;49m[38;5;124;43mdate[39;49m[38;5;124;43m'[39;49m[43m)[49m[38;5;241;43m.[39;49m[43mfirst[49m[43m([49m[43m)[49m[43m[[49m[38;5;124;43m'[39;49m[38;5;124;43m1987-07[39;49m[38;5;124;43m'[39;49m[43m][49m[38;5;241m.[39miloc[:,[38;5;241m4[39m:]

File [0;32m~/miniforge3/envs/octave/lib/python3.11/site-packages/pandas/core/frame.py:4090[0m, in [0;36mDataFrame.__getitem__[0;34m(self, key)[0m
[1;32m   4088[0m [38;5;28;01mif[39;00m [38;5;28mself[39m[38;5;241m.[39mcolumns[38;5;241m.[39mnlevels [38;5;241m>[39m [38;5;241m1[39m:
[1;32m   4089[0m     [38;5;28;01mreturn[39;00m [38;5;28mself[39m[38;5;241m.[39m_getitem_multilevel(key)
[0;32m-> 4090[0m indexer [38;5;241m=[39m [38;5;28;43mself[39;49m[38;5;241;43m.[39;49m[43mcolumns[49m[38;5;241;43m.[39;49m[43mget_loc[49m[43m([49m[43mkey[49m[43m)[49m
[1;32m   4091[0m [38;5;28;01mif[39;00m is_integer(indexer):
[1;32m   4092[0m     indexer [38;5;241m=[39m [indexer]

File [0;32m~/miniforge3/envs/octave/lib/python3.11/site-packages/pandas/core/indexes/base.py:3809[0m, in [0;36mIndex.get_loc[0;34m(self, key)[0m
[1;32m   3804[0m     [38;5;28;01mif[39;00m [38;5;28misinstance[39m(casted_key, [38;5;28mslice[39m) [38;5;129;01mor[39;00m (
[1;32m   3805[0m         [38;5;28misinstance[39m(casted_key, abc[38;5;241m.[39mIterable)
[1;32m   3806[0m         [38;5;129;01mand[39;00m [38;5;28many[39m([38;5;28misinstance[39m(x, [38;5;28mslice[39m) [38;5;28;01mfor[39;00m x [38;5;129;01min[39;00m casted_key)
[1;32m   3807[0m     ):
[1;32m   3808[0m         [38;5;28;01mraise[39;00m InvalidIndexError(key)
[0;32m-> 3809[0m     [38;5;28;01mraise[39;00m [38;5;167;01mKeyError[39;00m(key) [38;5;28;01mfrom[39;00m [38;5;21;01merr[39;00m
[1;32m   3810[0m [38;5;28;01mexcept[39;00m [38;5;167;01mTypeError[39;00m:
[1;32m   3811[0m     [38;5;66;03m# If we have a listlike key, _check_indexing_error will raise[39;00m
[1;32m   3812[0m     [38;5;66;03m#  InvalidIndexError. Otherwise we fall through and re-raise[39;00m
[1;32m   3813[0m     [38;5;66;03m#  the TypeError.[39;00m
[1;32m   3814[0m     [38;5;28mself[39m[38;5;241m.[39m_check_indexing_error(key)

[0;31mKeyError[0m: '1987-07'

